Workbook
Name LeasUp: #REF!
Name LeasUp: #REF!
Name Master: MASTER_UNIFIED_PORTFOLIO!$A:$AC
Name PayBack: #REF!
Name PayBack: #REF!
Name SBDATA: Dashboard_Data!$AE$1:$AH$20
Name Slicer_Lease_Up_Potential1: #N/A
Name Slicer_Lease_Up_Potential1: #N/A
Name Slicer_Site_classification1: #N/A
Name Slicer_Site_classification1: #N/A
Name Slicer_State1: #N/A
Name Slicer_State1: #N/A
Name Unleased: #REF!
Name Unleased: #REF!

Sheet Executive_Dashboard
B40: STRATEGIC INSIGHTS
B41: Pillar / Strategic Area | D41: Key Metric & Insight | H41: Risk / Opportunity | L41: Recommendation
B42: Pillar 1: Density & Growth | D42: ="High Lease-Up Potential covers " & TEXT(Dashboard_Data!AF7,"0.0%") & " (" & Dashboard_Data!AF5 & " of " & Dashboard_Data!AF4 & ") of candidate sites, concentrated in Urban (100%) and Suburban (97%) markets." -> High Lease-Up Potential covers 70.5% (299 of 424) of candidate sites, concentrated in Urban (100%) and Suburban (97%) markets. | H42: ="Opportunity: dense Urban/Suburban markets show near-universal co-location demand; Rural is a 41% split market." -> Opportunity: dense Urban/Suburban markets show near-universal co-location demand; Rural is a 41% split market. | L42: ="Fast-track sales outreach in Urban/Suburban; treat Rural as case-by-case, not a blanket push." -> Fast-track sales outreach in Urban/Suburban; treat Rural as case-by-case, not a blanket push.
B43: Pillar 2: Structural Profile | D43: ="Dominant structure type is " & Dashboard_Data!AF15 & " at " & TEXT(Dashboard_Data!AF16,"0.0%") & " of the candidate pool." -> Dominant structure type is SST at 60.8% of the candidate pool. | H43: Opportunity: SST towers show the strongest lease-up flag rate of any structure type. | L43: Prioritize SST inventory for near-term co-location sales motion.
B44: Pillar 3: Financial Profile | D44: ="Avg. CAPEX per site: " & TEXT(Dashboard_Data!AF8,"$#,##0") & ". " & TEXT(Dashboard_Data!AF10/Dashboard_Data!AF2,"0%") & " of the portfolio (" & Dashboard_Data!AF10 & " sites) sits in the 10+ year payback tier." -> Avg. CAPEX per site: $71,472. 50% of the portfolio (248 sites) sits in the 10+ year payback tier. | H44: ="Risk: High-Potential sites average " & TEXT(Dashboard_Data!AF13,"0.0") & " yrs anchor-only payback vs. " & TEXT(Dashboard_Data!AF14,"0.0") & " yrs for Low-Potential." -> Risk: High-Potential sites average 12.6 yrs anchor-only payback vs. 4.9 yrs for Low-Potential. | L44: ="Target the 10+ year tier first: " & TEXT(Dashboard_Data!AF12,"0.0%") & " of it is already flagged High-Potential." -> Target the 10+ year tier first: 84.3% of it is already flagged High-Potential.
B45: Pillar 4: Age Profile | D45: ="Site vintage varies across the portfolio (2017–2022 build years); newer, higher-CAPEX sites skew toward the slower anchor-only payback tiers." -> Site vintage varies across the portfolio (2017–2022 build years); newer, higher-CAPEX sites skew toward the slower anchor-only payback tiers. | H45: ="Risk: newer / larger-CAPEX builds take longer to recover on anchor rent alone, before any lease-up is realized." -> Risk: newer / larger-CAPEX builds take longer to recover on anchor rent alone, before any lease-up is realized. | L45: ="Sequence lease-up sales efforts to reach newer, high-CAPEX sites early — they benefit most from a 2nd tenant." -> Sequence lease-up sales efforts to reach newer, high-CAPEX sites early — they benefit most from a 2nd tenant.

Sheet Dashboard_Data
A1: Site Number | B1: Lease_Up_Potential | C1: Site classification | D1: Tower Type | E1: Year Built | F1: Payback_Years | G1: Payback_Category | J1: Classification | K1: High Potential | L1: Low Potential | N1: Payback Category | O1: Site Count | P1: Share of Portfolio | Q1: Lease-Up Potential | R1: Avg Payback (Yrs) | S1: Site Count | U1: Payback Category | V1: High Potential | W1: Low Potential | Y1: Tower Type | Z1: High Potential | AA1: Low Potential | AB1: Total | AE1: KPI
A2: 405 | B2: High Lease Up Potential | C2: Urban | D2: SST | E2: 2022 | F2: 20.634324 | G2: 10+ years Pay Back | J2: Rural | K2: =COUNTIFS($C$2:$C$425,$J2,$B$2:$B$425,"High Lease Up Potential") -> 83 | L2: =COUNTIFS($C$2:$C$425,$J2,$B$2:$B$425,"Low Lease Up Potential") -> 120 | N2: 1-5 years Pay Back | O2: 157 | P2: 0.314 | Q2: High Lease Up Potential | R2: =AVERAGEIFS($F$2:$F$425,$B$2:$B$425,$Q2) -> 12.641557 | S2: =COUNTIFS($B$2:$B$425,$Q2) -> 299 | U2: 1-5 years Pay Back | V2: =COUNTIFS($B$2:$B$425,"High Lease Up Potential",$G$2:$G$425,$U2) -> 47 | W2: =COUNTIFS($B$2:$B$425,"Low Lease Up Potential",$G$2:$G$425,$U2) -> 81 | Y2: SST | Z2: =COUNTIFS($D$2:$D$425,$Y2,$B$2:$B$425,"High Lease Up Potential") -> 195 | AA2: =COUNTIFS($D$2:$D$425,$Y2,$B$2:$B$425,"Low Lease Up Potential") -> 63 | AB2: =Z2+AA2 -> 258 | AE2: Total Sites | AF2: 500
A3: 233 | B3: High Lease Up Potential | C3: Urban | D3: SST | E3: 2019 | F3: 16.872197 | G3: 10+ years Pay Back | J3: Suburban | K3: =COUNTIFS($C$2:$C$425,$J3,$B$2:$B$425,"High Lease Up Potential") -> 179 | L3: =COUNTIFS($C$2:$C$425,$J3,$B$2:$B$425,"Low Lease Up Potential") -> 5 | N3: 5-10 years Pay Back | O3: 95 | P3: 0.19 | Q3: Low Lease Up Potential | R3: =AVERAGEIFS($F$2:$F$425,$B$2:$B$425,$Q3) -> 4.9435001 | S3: =COUNTIFS($B$2:$B$425,$Q3) -> 125 | U3: 5-10 years Pay Back | V3: =COUNTIFS($B$2:$B$425,"High Lease Up Potential",$G$2:$G$425,$U3) -> 43 | W3: =COUNTIFS($B$2:$B$425,"Low Lease Up Potential",$G$2:$G$425,$U3) -> 39 | Y3: Monopole | Z3: =COUNTIFS($D$2:$D$425,$Y3,$B$2:$B$425,"High Lease Up Potential") -> 97 | AA3: =COUNTIFS($D$2:$D$425,$Y3,$B$2:$B$425,"Low Lease Up Potential") -> 52 | AB3: =Z3+AA3 -> 149 | AE3: Already Multi-Tenant Sites | AF3: =AF2-AF4 -> 76
A4: 403 | B4: High Lease Up Potential | C4: Urban | D4: SST | E4: 2021 | F4: 15.13287 | G4: 10+ years Pay Back | J4: Urban | K4: =COUNTIFS($C$2:$C$425,$J4,$B$2:$B$425,"High Lease Up Potential") -> 37 | L4: =COUNTIFS($C$2:$C$425,$J4,$B$2:$B$425,"Low Lease Up Potential") -> 0 | N4: 10+ years Pay Back | O4: 248 | P4: 0.496 | U4: 10+ years Pay Back | V4: =COUNTIFS($B$2:$B$425,"High Lease Up Potential",$G$2:$G$425,$U4) -> 209 | W4: =COUNTIFS($B$2:$B$425,"Low Lease Up Potential",$G$2:$G$425,$U4) -> 5 | Y4: Guyed Tower | Z4: =COUNTIFS($D$2:$D$425,$Y4,$B$2:$B$425,"High Lease Up Potential") -> 3 | AA4: =COUNTIFS($D$2:$D$425,$Y4,$B$2:$B$425,"Low Lease Up Potential") -> 7 | AB4: =Z4+AA4 -> 10 | AE4: Candidate Pool (Unleased) | AF4: 424
A5: 486 | B5: High Lease Up Potential | C5: Urban | D5: Monopole | E5: 2022 | F5: 14.610737 | G5: 10+ years Pay Back | Y5: Stealth - Flagpole | Z5: =COUNTIFS($D$2:$D$425,$Y5,$B$2:$B$425,"High Lease Up Potential") -> 3 | AA5: =COUNTIFS($D$2:$D$425,$Y5,$B$2:$B$425,"Low Lease Up Potential") -> 2 | AB5: =Z5+AA5 -> 5 | AE5: High Potential Sites | AF5: 299
A6: 190 | B6: High Lease Up Potential | C6: Urban | D6: Monopole | E6: 2019 | F6: 11.189251 | G6: 10+ years Pay Back | Y6: Stealth - Monopine | Z6: =COUNTIFS($D$2:$D$425,$Y6,$B$2:$B$425,"High Lease Up Potential") -> 1 | AA6: =COUNTIFS($D$2:$D$425,$Y6,$B$2:$B$425,"Low Lease Up Potential") -> 1 | AB6: =Z6+AA6 -> 2 | AE6: Low Potential Sites | AF6: 125
A7: 130 | B7: High Lease Up Potential | C7: Urban | D7: SST | E7: 2019 | F7: 13.241903 | G7: 10+ years Pay Back | AE7: High Potential Share | AF7: =AF5/AF4 -> 0.70518868
A8: 359 | B8: High Lease Up Potential | C8: Urban | D8: SST | E8: 2021 | F8: 18.365895 | G8: 10+ years Pay Back | AE8: Avg CAPEX / Site (all 500) | AF8: 71472.432
A9: 236 | B9: High Lease Up Potential | C9: Urban | D9: SST | E9: 2019 | F9: 16.299667 | G9: 10+ years Pay Back | AE9: Total Portfolio CAPEX | AF9: 35736216
A10: 271 | B10: High Lease Up Potential | C10: Urban | D10: SST | E10: 2020 | F10: 13.830288 | G10: 10+ years Pay Back | AE10: Sites in 10+ Yr Payback Tier | AF10: 248 | AG10: =AF10/AF2 -> 0.496
A11: 133 | B11: High Lease Up Potential | C11: Urban | D11: SST | E11: 2019 | F11: 18.935691 | G11: 10+ years Pay Back | AE11: ...of which High Potential | AF11: =V4 -> 209
A12: 252 | B12: High Lease Up Potential | C12: Urban | D12: SST | E12: 2019 | F12: 15.500168 | G12: 10+ years Pay Back | AE12: ...share of 10+ tier that is High Potential | AF12: =AF11/AF10 -> 0.84274194
A13: 500 | B13: High Lease Up Potential | C13: Urban | D13: SST | E13: 2022 | F13: 57.80119 | G13: 10+ years Pay Back | AE13: Avg Payback - High Potential (anchor-only) | AF13: =R2 -> 12.641557
A14: 426 | B14: High Lease Up Potential | C14: Urban | D14: SST | E14: 2022 | F14: 59.485143 | G14: 10+ years Pay Back | AE14: Avg Payback - Low Potential (anchor-only) | AF14: =R3 -> 4.9435001
A15: 291 | B15: High Lease Up Potential | C15: Urban | D15: SST | E15: 2021 | F15: 21.66 | G15: 10+ years Pay Back | AE15: Dominant Tower Type (all unleased) | AF15: =INDEX(Y2:Y6,MATCH(MAX(AB2:AB6),AB2:AB6,0)) -> SST
A16: 139 | B16: High Lease Up Potential | C16: Urban | D16: SST | E16: 2019 | F16: 12.978576 | G16: 10+ years Pay Back | AE16: Dominant Tower Type Share | AF16: =MAX(AB2:AB6)/AF4 -> 0.60849057
A17: 496 | B17: High Lease Up Potential | C17: Suburban | D17: SST | E17: 2022 | F17: 14.704861 | G17: 10+ years Pay Back
A18: 310 | B18: High Lease Up Potential | C18: Suburban | D18: SST | E18: 2021 | F18: 15.138167 | G18: 10+ years Pay Back
A19: 345 | B19: High Lease Up Potential | C19: Suburban | D19: SST | E19: 2021 | F19: 17.615048 | G19: 10+ years Pay Back
A20: 388 | B20: High Lease Up Potential | C20: Suburban | D20: SST | E20: 2021 | F20: 15.18832 | G20: 10+ years Pay Back
A21: 425 | B21: High Lease Up Potential | C21: Urban | D21: Monopole | E21: 2022 | F21: 17.17285 | G21: 10+ years Pay Back
A22: 449 | B22: High Lease Up Potential | C22: Suburban | D22: SST | E22: 2022 | F22: 15.279236 | G22: 10+ years Pay Back
A23: 262 | B23: High Lease Up Potential | C23: Urban | D23: SST | E23: 2020 | F23: 21.787917 | G23: 10+ years Pay Back
A24: 259 | B24: High Lease Up Potential | C24: Urban | D24: SST | E24: 2020 | F24: 20.385606 | G24: 10+ years Pay Back
A25: 109 | B25: High Lease Up Potential | C25: Urban | D25: SST | E25: 2018 | F25: 14.489389 | G25: 10+ years Pay Back
A26: 67 | B26: High Lease Up Potential | C26: Urban | D26: SST | E26: 2018 | F26: 14.898315 | G26: 10+ years Pay Back
A27: 58 | B27: High Lease Up Potential | C27: Urban | D27: SST | E27: 2018 | F27: 14.397758 | G27: 10+ years Pay Back
A28: 4 | B28: High Lease Up Potential | C28: Urban | D28: SST | E28: 2017 | F28: 15.35942 | G28: 10+ years Pay Back
... A425: 484 | B425: Low Lease Up Potential | C425: Rural | D425: Stealth - Monopine | E425: 2022 | F425: 11.705729 | G425: 10+ years Pay Back

Sheet MASTER_UNIFIED_PORTFOLIO
A1: Site Number | B1: Site classification | C1: State | D1: Tower Type | E1: Height | F1: Year Built | G1: Anchor Tenant Name | H1: Capex | I1: Additional_Tenant_Count | J1: Stack_Rank | K1: Site Number.1 | L1: Lease_Up_Potential | M1: Leaseup_Score | N1: Site classification.1 | O1: State.1 | P1: Tower Type.1 | Q1: Height.1 | R1: Year Built.1 | S1: Anchor Tenant Name.1 | T1: Capex.1 | U1: Site Number.2 | V1: Site classification.2 | W1: State.2 | X1: Capex.2 | Y1: Anchor Tenant Starting Monthly Rent | Z1: Ground Lease Rent OPEX | AA1: Net_Annual_Income | AB1: Payback_Years | AC1: Payback_Category
A2: 69 | B2: Suburban | C2: OR | D2: SST | E2: 165 | F2: 2018 | G2: Tenant A | H2: 92378 | I2: 0 | J2: 5 | K2: 190 | L2: High Lease Up Potential | M2: 92 | N2: Urban | O2: TX | P2: Monopole | Q2: 205 | R2: 2019 | S2: Tenant A | T2: 87276.16 | U2: 5 | V2: Rural | W2: OR | X2: 20330 | Y2: 950 | Z2: 175 | AA2: 9300 | AB2: 2.1860215 | AC2: 1-5 years Pay Back
A3: 259 | B3: Urban | C3: AZ | D3: SST | E3: 155 | F3: 2020 | G3: Tenant A | H3: 134545 | I3: 0 | J3: 94 | K3: 124 | L3: High Lease Up Potential | M3: 80 | N3: Suburban | O3: TX | P3: SST | Q3: 145 | R3: 2019 | S3: Tenant B | T3: 100567.5 | U3: 94 | V3: Rural | W3: OR | X3: 21810.25 | Y3: 875 | Z3: 350 | AA3: 6300 | AB3: 3.4619444 | AC3: 1-5 years Pay Back
A4: 472 | B4: Suburban | C4: FL | D4: Guyed Tower | E4: 140 | F4: 2022 | G4: Tenant D | H4: 117221.25 | I4: 0 | J4: 61 | K4: 201 | L4: High Lease Up Potential | M4: 84 | N4: Suburban | O4: TX | P4: SST | Q4: 170 | R4: 2019 | S4: Tenant D | T4: 90472.06 | U4: 61 | V4: Rural | W4: AZ | X4: 21848.4 | Y4: 825 | Z4: 375 | AA4: 5400 | AB4: 4.046 | AC4: 1-5 years Pay Back
A5: 365 | B5: Rural | C5: AZ | D5: SST | E5: 155 | F5: 2021 | G5: Tenant B | H5: 33969.6 | I5: 0 | J5: 206 | K5: 84 | L5: High Lease Up Potential | M5: 71 | N5: Suburban | O5: FL | P5: Monopole | Q5: 170 | R5: 2018 | S5: Tenant C | T5: 88603.84 | U5: 206 | V5: Rural | W5: PA | X5: 21913.38 | Y5: 950 | Z5: 350 | AA5: 7200 | AB5: 3.043525 | AC5: 1-5 years Pay Back
A6: 78 | B6: Suburban | C6: FL | D6: Monopole | E6: 140 | F6: 2018 | G6: Tenant B | H6: 99832.95 | I6: 0 | J6: 223 | K6: 466 | L6: High Lease Up Potential | M6: 70 | N6: Rural | O6: PA | P6: SST | Q6: 200 | R6: 2022 | S6: Tenant C | T6: 32921.25 | U6: 223 | V6: Rural | W6: AZ | X6: 22600.6 | Y6: 950 | Z6: 225 | AA6: 8700 | AB6: 2.5977701 | AC6: 1-5 years Pay Back
A7: 148 | B7: Rural | C7: AZ | D7: SST | E7: 145 | F7: 2019 | G7: Tenant C | H7: 39775.32 | I7: 0 | J7: 81 | K7: 307 | L7: High Lease Up Potential | M7: 82 | N7: Suburban | O7: AZ | P7: Monopole | Q7: 185 | R7: 2021 | S7: Tenant C | T7: 114187.2 | U7: 81 | V7: Rural | W7: PA | X7: 22632.19 | Y7: 950 | Z7: 300 | AA7: 7800 | AB7: 2.9015628 | AC7: 1-5 years Pay Back
A8: 360 | B8: Rural | C8: PA | D8: SST | E8: 215 | F8: 2021 | G8: Tenant B | H8: 42669.6 | I8: 0 | J8: 45 | K8: 400 | L8: High Lease Up Potential | M8: 85 | N8: Suburban | O8: PA | P8: SST | Q8: 230 | R8: 2021 | S8: Tenant A | T8: 104485.2 | U8: 45 | V8: Rural | W8: OR | X8: 22866 | Y8: 950 | Z8: 275 | AA8: 8100 | AB8: 2.822963 | AC8: 1-5 years Pay Back
A9: 343 | B9: Rural | C9: FL | D9: Monopole | E9: 205 | F9: 2021 | G9: Tenant B | H9: 33500.4 | I9: 0 | J9: 42 | K9: 43 | L9: High Lease Up Potential | M9: 86 | N9: Urban | O9: TX | P9: Monopole | Q9: 160 | R9: 2018 | S9: Tenant C | T9: 108223.5 | U9: 42 | V9: Rural | W9: PA | X9: 23124.4 | Y9: 950 | Z9: 300 | AA9: 7800 | AB9: 2.9646667 | AC9: 1-5 years Pay Back
A10: 373 | B10: Rural | C10: PA | D10: Monopole | E10: 165 | F10: 2021 | G10: Tenant C | H10: 28458 | I10: 0 | J10: 46 | K10: 284 | L10: High Lease Up Potential | M10: 85 | N10: Suburban | O10: OR | P10: SST | Q10: 220 | R10: 2021 | S10: Tenant A | T10: 104505.52 | U10: 46 | V10: Rural | W10: PA | X10: 23549.4 | Y10: 950 | Z10: 275 | AA10: 8100 | AB10: 2.9073333 | AC10: 1-5 years Pay Back
A11: 161 | B11: Rural | C11: AZ | D11: SST | E11: 160 | F11: 2019 | G11: Tenant C | H11: 37293.3 | I11: 0 | J11: 234 | K11: 381 | L11: High Lease Up Potential | M11: 70 | N11: Rural | O11: OR | P11: SST | Q11: 225 | R11: 2021 | S11: Tenant B | T11: 46520.4 | U11: 234 | V11: Rural | W11: AZ | X11: 23569.7 | Y11: 975 | Z11: 225 | AA11: 9000 | AB11: 2.6188556 | AC11: 1-5 years Pay Back
A12: 491 | B12: Rural | C12: OR | D12: Monopole | E12: 225 | F12: 2022 | G12: Tenant B | H12: 29931.25 | I12: 0 | J12: 63 | K12: 202 | L12: High Lease Up Potential | M12: 84 | N12: Suburban | O12: TX | P12: SST | Q12: 175 | R12: 2019 | S12: Tenant B | T12: 107986.44 | U12: 63 | V12: Rural | W12: PA | X12: 23647.52 | Y12: 975 | Z12: 350 | AA12: 7500 | AB12: 3.1530027 | AC12: 1-5 years Pay Back
A13: 463 | B13: Rural | C13: PA | D13: SST | E13: 180 | F13: 2022 | G13: Tenant D | H13: 37098.75 | I13: 0 | J13: 214 | K13: 44 | L13: High Lease Up Potential | M13: 71 | N13: Suburban | O13: PA | P13: Monopole | Q13: 185 | R13: 2018 | S13: Tenant A | T13: 110680.5 | U13: 214 | V13: Rural | W13: TX | X13: 23819.4 | Y13: 975 | Z13: 350 | AA13: 7500 | AB13: 3.17592 | AC13: 1-5 years Pay Back
... A18: 208 | B18: Rural | C18: TX | D18: Monopole | E18: 215 | F18: 2019 | G18: Tenant D | H18: 26345.52 | I18: 0 | J18: 25 | K18: 67 | L18: High Lease Up Potential | M18: 89 | N18: Urban | O18: FL | P18: SST | Q18: 225 | R18: 2018 | S18: Tenant A | T18: 98328.88 | U18: 25 | V18: Rural | W18: TX | X18: 24532 | Y18: 875 | Z18: 200 | AA18: 8100 | AB18: 3.028642 | AC18: 1-5 years Pay Back
A19: 159 | B19: Rural | C19: PA | D19: Monopole | E19: 140 | F19: 2019 | G19: Tenant D | H19: 25215.300000000003 | I19: 0 | J19: 83 | K19: 268 | L19: High Lease Up Potential | M19: 82 | N19: Suburban | O19: PA | P19: SST | Q19: 225 | R19: 2020 | S19: Tenant A | T19: 115236.25 | U19: 83 | V19: Rural | W19: TX | X19: 24696.31 | Y19: 825 | Z19: 225 | AA19: 7200 | AB19: 3.4300431 | AC19: 1-5 years Pay Back
A20: 268 | B20: Suburban | C20: PA | D20: SST | E20: 225 | F20: 2020 | G20: Tenant A | H20: 115236.25 | I20: 0 | J20: 404 | K20: 267 | L20: Low Lease Up Potential | M20: 56 | N20: Rural | O20: OR | P20: SST | Q20: 110 | R20: 2020 | S20: Tenant C | T20: 38785 | U20: 404 | V20: Rural | W20: OR | X20: 24715.2 | Y20: 975 | Z20: 350 | AA20: 7500 | AB20: 3.29536 | AC20: 1-5 years Pay Back
A21: 276 | B21: Suburban | C21: FL | D21: SST | E21: 195 | F21: 2020 | G21: Tenant D | H21: 122871.25 | I21: 0 | J21: 32 | K21: 75 | L21: High Lease Up Potential | M21: 87 | N21: Urban | O21: AZ | P21: SST | Q21: 130 | R21: 2018 | S21: Tenant B | T21: 95874.46 | U21: 32 | V21: Rural | W21: FL | X21: 24868 | Y21: 950 | Z21: 325 | AA21: 7500 | AB21: 3.3157333 | AC21: 1-5 years Pay Back
A22: 448 | B22: Rural | C22: TX | D22: SST | E22: 140 | F22: 2022 | G22: Tenant C | H22: 48842.07 | I22: 0 | J22: 213 | K22: 111 | L22: High Lease Up Potential | M22: 71 | N22: Suburban | O22: OR | P22: Monopole | Q22: 190 | R22: 2018 | S22: Tenant D | T22: 108838.8 | U22: 213 | V22: Rural | W22: OR | X22: 25100.9 | Y22: 975 | Z22: 275 | AA22: 8400 | AB22: 2.9882024 | AC22: 1-5 years Pay Back
A23: 223 | B23: Rural | C23: AZ | D23: Monopole | E23: 170 | F23: 2019 | G23: Tenant A | H23: 22600.6 | I23: 0 | J23: 399 | K23: 128 | L23: Low Lease Up Potential | M23: 56 | N23: Rural | O23: FL | P23: SST | Q23: 115 | R23: 2019 | S23: Tenant D | T23: 36090.88 | U23: 399 | V23: Rural | W23: TX | X23: 25496.4 | Y23: 950 | Z23: 200 | AA23: 9000 | AB23: 2.8329333 | AC23: 1-5 years Pay Back
A24: 73 | B24: Suburban | C24: FL | D24: Monopole | E24: 140 | F24: 2018 | G24: Tenant A | H24: 84035.7 | I24: 0 | J24: 6 | K24: 130 | L24: High Lease Up Potential | M24: 92 | N24: Urban | O24: OR | P24: SST | Q24: 220 | R24: 2019 | S24: Tenant C | T24: 95341.7 | U24: 6 | V24: Rural | W24: AZ | X24: 25682 | Y24: 875 | AA24: 10500 | AB24: 2.4459048 | AC24: 1-5 years Pay Back
A25: 379 | B25: Suburban | C25: FL | D25: SST | E25: 100 | F25: 2021 | G25: Tenant A | H25: 104562 | I25: 0 | J25: 357 | K25: 105 | L25: Low Lease Up Potential | M25: 61 | N25: Rural | O25: PA | P25: SST | Q25: 160 | R25: 2018 | S25: Tenant D | T25: 33072.9 | U25: 357 | V25: Rural | W25: AZ | X25: 25762.8 | Y25: 950 | Z25: 250 | AA25: 8400 | AB25: 3.067 | AC25: 1-5 years Pay Back
A26: 246 | B26: Rural | C26: PA | D26: SST | E26: 200 | F26: 2019 | G26: Tenant C | H26: 37101.06 | I26: 0 | J26: 288 | K26: 65 | L26: High Lease Up Potential | M26: 67 | N26: Suburban | O26: PA | P26: Monopole | Q26: 155 | R26: 2018 | S26: Tenant A | T26: 107742.12 | U26: 288 | V26: Rural | W26: PA | X26: 25816.8 | Y26: 950 | Z26: 325 | AA26: 7500 | AB26: 3.44224 | AC26: 1-5 years Pay Back
A27: 471 | B27: Suburban | C27: OR | D27: SST | E27: 185 | F27: 2022 | G27: Tenant D | H27: 133112.5 | I27: 0 | J27: 60 | K27: 390 | L27: High Lease Up Potential | M27: 85 | N27: Suburban | O27: FL | P27: SST | Q27: 205 | R27: 2021 | S27: Tenant B | T27: 130543.2 | U27: 60 | V27: Rural | W27: PA | X27: 26023.92 | Y27: 975 | Z27: 200 | AA27: 9300 | AB27: 2.798271 | AC27: 1-5 years Pay Back
A28: 248 | B28: Rural | C28: OR | D28: Monopole | E28: 160 | F28: 2019 | G28: Tenant C | H28: 38049.48 | I28: 0 | J28: 401 | K28: 121 | L28: Low Lease Up Potential | M28: 56 | N28: Rural | O28: PA | P28: SST | Q28: 115 | R28: 2019 | S28: Tenant D | T28: 37370.3 | U28: 401 | V28: Rural | W28: OR | X28: 26030.4 | Y28: 825 | Z28: 350 | AA28: 5700 | AB28: 4.5667368 | AC28: 1-5 years Pay Back
A29: 242 | B29: Urban | C29: FL | D29: Stealth - Flagpole | E29: 160 | F29: 2019 | G29: Tenant C | H29: 100640.64 | I29: 0 | J29: 92 | K29: 239 | L29: High Lease Up Potential | M29: 81 | N29: Urban | O29: FL | P29: SST | Q29: 110 | R29: 2019 | S29: Tenant D | T29: 90693 | U29: 92 | V29: Rural | W29: AZ | X29: 26047.67 | Y29: 975 | Z29: 325 | AA29: 7800 | AB29: 3.3394449 | AC29: 1-5 years Pay Back
B30: N/A | C30: N/A | L30: Pending Review | U30: 465 | V30: Rural | W30: OR | X30: 26068.75 | Y30: 950 | Z30: 250 | AA30: 8400 | AB30: 3.1034226 | AC30: 1-5 years Pay Back
A31: 307 | B31: Suburban | C31: AZ | D31: Monopole | E31: 185 | F31: 2021 | G31: Tenant C | H31: 114187.2 | I31: 0 | J31: 150 | K31: 116 | L31: High Lease Up Potential | M31: 76 | N31: Suburban | O31: FL | P31: SST | Q31: 160 | R31: 2018 | S31: Tenant A | T31: 89028.16 | U31: 150 | V31: Rural | W31: PA | X31: 26139.24 | Y31: 950 | Z31: 350 | AA31: 7200 | AB31: 3.63045 | AC31: 1-5 years Pay Back
A32: 390 | B32: Suburban | C32: FL | D32: SST | E32: 205 | F32: 2021 | G32: Tenant B | H32: 130543.2 | I32: 0 | J32: 208 | K32: 138 | L32: High Lease Up Potential | M32: 71 | N32: Suburban | O32: TX | P32: Monopole | Q32: 115 | R32: 2019 | S32: Tenant A | T32: 92045.16 | U32: 208 | V32: Rural | W32: TX | X32: 26345.52 | Y32: 825 | Z32: 175 | AA32: 7800 | AB32: 3.3776308 | AC32: 1-5 years Pay Back
A33: 202 | B33: Suburban | C33: TX | D33: SST | E33: 175 | F33: 2019 | G33: Tenant B | H33: 107986.44 | I33: 0 | J33: 87 | K33: 435 | L33: High Lease Up Potential | M33: 82 | N33: Suburban | O33: PA | P33: SST | Q33: 160 | R33: 2022 | S33: Tenant C | T33: 121287.84 | U33: 87 | V33: Rural | W33: AZ | X33: 26408.17 | Y33: 975 | Z33: 350 | AA33: 7500 | AB33: 3.5210893 | AC33: 1-5 years Pay Back
A34: 402 | B34: Rural | C34: OR | D34: Monopole | E34: 165 | F34: 2021 | G34: Tenant D | H34: 33697.2 | I34: 0 | J34: 311 | K34: 170 | L34: Low Lease Up Potential | M34: 64 | N34: Rural | O34: FL | P34: SST | Q34: 195 | R34: 2019 | S34: Tenant D | T34: 30138.48 | U34: 311 | V34: Rural | W34: TX | X34: 26619.6 | Y34: 875 | Z34: 375 | AA34: 6000 | AB34: 4.4366 | AC34: 1-5 years Pay Back
A35: 388 | B35: Suburban | C35: TX | D35: SST | E35: 225 | F35: 2021 | G35: Tenant D | H35: 113912.4 | I35: 0 | J35: 308 | K35: 55 | L35: Low Lease Up Potential | M35: 64 | N35: Rural | O35: TX | P35: Monopole | Q35: 230 | R35: 2018 | S35: Tenant D | T35: 28861.63 | U35: 308 | V35: Rural | W35: AZ | X35: 26750.4 | Y35: 875 | Z35: 175 | AA35: 8400 | AB35: 3.1845714 | AC35: 1-5 years Pay Back
A36: 454 | B36: Suburban | C36: OR | D36: SST | E36: 200 | F36: 2022 | G36: Tenant B | H36: 108716.01 | I36: 0 | J36: 56 | K36: 478 | L36: High Lease Up Potential | M36: 85 | N36: Suburban | O36: TX | P36: Monopole | Q36: 220 | R36: 2022 | S36: Tenant D | T36: 124838.75 | U36: 56 | V36: Rural | W36: TX | X36: 26795.6 | Y36: 825 | Z36: 275 | AA36: 6600 | AB36: 4.0599394 | AC36: 1-5 years Pay Back
A37: 127 | B37: Rural | C37: PA | D37: Monopole | E37: 170 | F37: 2019 | G37: Tenant D | H37: 28017.92 | I37: 0 | J37: 13 | K37: 426 | L37: High Lease Up Potential | M37: 92 | N37: Urban | O37: PA | P37: SST | Q37: 185 | R37: 2022 | S37: Tenant B | T37: 124918.8 | U37: 13 | V37: Rural | W37: OR | X37: 27072 | Y37: 950 | Z37: 225 | AA37: 8700 | AB37: 3.1117241 | AC37: 1-5 years Pay Back
B38: N/A | C38: N/A | L38: Pending Review | U38: 497 | V38: Rural | W38: PA | X38: 27095 | Y38: 875 | Z38: 325 | AA38: 6600 | AB38: 4.105303 | AC38: 1-5 years Pay Back
A39: 267 | B39: Rural | C39: OR | D39: SST | E39: 110 | F39: 2020 | G39: Tenant C | H39: 38785 | I39: 0 | J39: 146 | K39: 178 | L39: High Lease Up Potential | M39: 77 | N39: Suburban | O39: OR | P39: Monopole | Q39: 205 | R39: 2019 | S39: Tenant C | T39: 108794.88 | U39: 146 | V39: Rural | W39: OR | X39: 27133.88 | Y39: 950 | Z39: 250 | AA39: 8400 | AB39: 3.2302238 | AC39: 1-5 years Pay Back
B40: N/A | C40: N/A | L40: Pending Review | U40: 431 | V40: Rural | W40: OR | X40: 27138.72 | Y40: 875 | Z40: 300 | AA40: 6900 | AB40: 3.9331478 | AC40: 1-5 years Pay Back
A41: 228 | B41: Rural | C41: OR | D41: SST | E41: 185 | F41: 2019 | G41: Tenant A | H41: 36587.16 | I41: 0 | J41: 342 | K41: 218 | L41: Low Lease Up Potential | M41: 62 | N41: Rural | O41: FL | P41: Monopole | Q41: 205 | R41: 2019 | S41: Tenant D | T41: 35850.6 | U41: 342 | V41: Rural | W41: PA | X41: 27154.8 | Y41: 975 | Z41: 175 | AA41: 9600 | AB41: 2.828625 | AC41: 1-5 years Pay Back
A42: 284 | B42: Suburban | C42: OR | D42: SST | E42: 220 | F42: 2021 | G42: Tenant A | H42: 104505.52 | I42: 0 | J42: 245 | K42: 196 | L42: High Lease Up Potential | M42: 69 | N42: Urban | O42: FL | P42: Stealth - Flagpole | Q42: 165 | R42: 2019 | S42: Tenant C | T42: 106497.14 | U42: 245 | V42: Rural | W42: TX | X42: 27254.88 | Y42: 975 | Z42: 325 | AA42: 7800 | AB42: 3.4942154 | AC42: 1-5 years Pay Back
A43: 322 | B43: Suburban | C43: OR | D43: Monopole | E43: 200 | F43: 2021 | G43: Tenant A | H43: 105723.6 | I43: 0 | J43: 350 | K43: 81 | L43: Low Lease Up Potential | M43: 61 | N43: Rural | O43: PA | P43: SST | Q43: 180 | R43: 2018 | S43: Tenant A | T43: 22632.19 | U43: 350 | V43: Rural | W43: OR | X43: 27264 | Y43: 950 | Z43: 325 | AA43: 7500 | AB43: 3.6352 | AC43: 1-5 years Pay Back
A44: 197 | B44: Suburban | C44: FL | D44: SST | E44: 95 | F44: 2019 | G44: Tenant B | H44: 115262.28 | I44: 0 | J44: 397 | K44: 414 | L44: Low Lease Up Potential | M44: 56 | N44: Rural | O44: PA | P44: Guyed Tower | Q44: 150 | R44: 2022 | S44: Tenant A | T44: 33428.94 | U44: 397 | V44: Rural | W44: AZ | X44: 27312 | Y44: 975 | Z44: 175 | AA44: 9600 | AB44: 2.845 | AC44: 1-5 years Pay Back
...

Sheet Pivots
A1: Density & Growth
A2: Sum of Site Number | B2: Column Labels
A3: Row Labels | B3: High Lease Up Potential | C3: Low Lease Up Potential | D3: (blank) | E3: Grand Total
A4: Rural | B4: 41779 | C4: 15294 | E4: 57073
A5: Suburban | B5: 26809 | C5: 18007 | E5: 44816
A6: Urban | B6: 5654 | C6: 3813 | E6: 9467
A7: (blank)
A8: Grand Total | B8: 74242 | C8: 37114 | E8: 111356
A9: Structural Profile
A10: Height | B10: (All)
A12: Sum of Site Number | B12: Column Labels
A13: Row Labels | B13: High Lease Up Potential | C13: Low Lease Up Potential | D13: Grand Total
A14: Guyed Tower | B14: 1952 | C14: 1103 | D14: 3055
A15: Monopole | B15: 23663 | C15: 15395 | D15: 39058
A16: SST | B16: 47076 | C16: 20420 | D16: 67496
A17: Stealth - Flagpole | B17: 703 | C17: 196 | D17: 899
A18: Stealth - Monopine | B18: 848 | D18: 848
A19: Grand Total | B19: 74242 | C19: 37114 | D19: 111356
A22: Financial Profile
A23: Row Labels | B23: Count of Site Number | C23: Average of Capex | D23: Average of Net_Annual_Income
A24: 1-5 years Pay Back | B24: 137 | C24: 74251.142 | D24: 8136.3057
A25: 10+ years Pay Back | B25: 212 | C25: 78400.671 | D25: 7219.3548
A26: 5-10 years Pay Back | B26: 75 | C26: 65241.6 | D26: 7092.6316
A27: Grand Total | B27: 424 | C27: 74759.61 | D27: 7483.2
A29: Age Profile
A30: Sum of Site Number | B30: Column Labels
A31: Row Labels | B31: High Lease Up Potential | C31: Low Lease Up Potential | D31: Grand Total
A32: 2015-2019 | B32: 21338 | C32: 7063 | D32: 28401
A33: 2020-2025 | B33: 52904 | C33: 30051 | D33: 82955
A34: Grand Total | B34: 74242 | C34: 37114 | D34: 111356

Sheet Calc
A2: Total Unleased Sites | B2: =COUNTA(UnLeased!A2:A500) -> 424 | C2: ="TOTAL UNLEASED SITES" & CHAR(10) & TEXT(COUNTA(UnLeased!C2:C500), "#,##0") -> TOTAL UNLEASED SITES 424
A3: High Potential Sites | B3: =COUNTIF(LeaseUp!C2:C500, "High Lease Up Potential") -> 299 | C3: ="HIGH POTENTIAL SITES" & CHAR(10) & TEXT(COUNTIF(LeaseUp!C2:C500, "High Lease Up Potential"), "#,##0") -> HIGH POTENTIAL SITES 299
A4: Low Potential Sites | B4: =COUNTIF(LeaseUp!C2:C500, "Low Lease Up Potential") -> 125 | C4: ="LOW POTENTIAL SITES" & CHAR(10) & TEXT(COUNTIF(LeaseUp!C2:C500, "Low Lease Up Potential"), "#,##0") -> LOW POTENTIAL SITES 125
A5: High Potential Share | B5: =TEXT(COUNTIF(LeaseUp!C2:C500, "High Lease Up Potential")/COUNTA(LeaseUp!A2:A500), "0.0%") -> 70.5% | C5: ="HIGH POTENTIAL SHARE" & CHAR(10) & TEXT(COUNTIF(LeaseUp!C2:C500, "High Lease Up Potential")/COUNTA(LeaseUp!A2:A500), "0.0%") -> HIGH POTENTIAL SHARE 70.5%
A6: Total Portfolio Capex | B6: =TEXT(SUM(PayBack!D2:D501), "$#,##0") -> $35,736,216 | C6: ="TOTAL PORTFOLIO CAPEX" & CHAR(10) & TEXT(SUM(PayBack!D2:D501), "$#,##0") -> TOTAL PORTFOLIO CAPEX $35,736,216
A7: Avg Payback Period | B7: =TEXT(AVERAGE(PayBack!H2:H501), "0.0") & " Yrs" -> 10.2 Yrs | C7: ="AVG PAYBACK PERIOD" & CHAR(10) & TEXT(AVERAGE(PayBack!H2:H501), "0.0") & " Yrs" -> AVG PAYBACK PERIOD 10.2 Yrs
A8: 1-5 Yr Payback | B8: =TEXT(COUNTIF(PayBack!I2:I500, "1-5 years Pay Back"), "#,##0") -> 157 | C8: ="1-5 YR PAYBACK SITES" & CHAR(10) & TEXT(COUNTIF(PayBack!I2:I500, "1-5 years Pay Back"), "#,##0") -> 1-5 YR PAYBACK SITES 157
A9: 5-10 yr Payback | B9: =TEXT(COUNTIF(PayBack!I2:I500, "5-10 years Pay Back"), "#,##0") -> 95 | C9: ="5-10 YR PAYBACK SITES" & CHAR(10) & TEXT(COUNTIF(PayBack!I2:I500, "5-10 years Pay Back"), "#,##0") -> 5-10 YR PAYBACK SITES 95
A10: 10 + Yr Payback | B10: =TEXT(COUNTIF(PayBack!I2:I500, "10+ years Pay Back"), "#,##0") -> 247 | C10: ="10+ YR PAYBACK SITES" & CHAR(10) & TEXT(COUNTIF(PayBack!I2:I500, "10+ years Pay Back"), "#,##0") -> 10+ YR PAYBACK SITES 247

Sheet UnLeased
A1: Site Number | B1: Site classification | C1: State | D1: Tower Type | E1: Height | F1: Year Built | G1: Anchor Tenant Name | H1: Capex | I1: Additional_Tenant_Count | M1: =SUM(H2:H425) -> 30793446
A2: 7 | B2: Suburban | C2: AZ | D2: SST | E2: 185 | F2: 2017 | G2: Tenant B | H2: 82296 | I2: 0
A3: 20 | B3: Suburban | C3: AZ | D3: Monopole | E3: 120 | F3: 2017 | G3: Tenant A | H3: 99848 | I3: 0
A4: 40 | B4: Suburban | C4: FL | D4: SST | E4: 210 | F4: 2018 | G4: Tenant B | H4: 85397.52 | I4: 0
A5: 68 | B5: Rural | C5: PA | D5: Monopole | E5: 195 | F5: 2018 | G5: Tenant D | H5: 37968.32 | I5: 0
A6: 69 | B6: Suburban | C6: OR | D6: SST | E6: 165 | F6: 2018 | G6: Tenant A | H6: 92378 | I6: 0
A7: 73 | B7: Suburban | C7: FL | D7: Monopole | E7: 140 | F7: 2018 | G7: Tenant A | H7: 84035.7 | I7: 0
A8: 76 | B8: Suburban | C8: OR | D8: SST | E8: 215 | F8: 2018 | G8: Tenant A | H8: 96011.45 | I8: 0
A9: 81 | B9: Rural | C9: PA | D9: SST | E9: 180 | F9: 2018 | G9: Tenant A | H9: 22632.19 | I9: 0
A10: 90 | B10: Rural | C10: FL | D10: Monopole | E10: 195 | F10: 2018 | G10: Tenant A | H10: 40276.09 | I10: 0
A11: 101 | B11: Urban | C11: FL | D11: Stealth - Flagpole | E11: 240 | F11: 2018 | G11: Tenant A | H11: 106028 | I11: 0
A12: 112 | B12: Suburban | C12: PA | D12: Monopole | E12: 135 | F12: 2018 | G12: Tenant C | H12: 108379.69 | I12: 0
A13: 118 | B13: Rural | C13: PA | D13: SST | E13: 210 | F13: 2018 | G13: Tenant A | H13: 26424.3 | I13: 0
... A425: 496 | B425: Suburban | C425: TX | D425: SST | E425: 225 | F425: 2022 | G425: Tenant A | H425: 105875 | I425: 0

Sheet LeaseUp
A1: Stack_Rank | B1: Site Number | C1: Lease_Up_Potential | D1: Leaseup_Score | E1: Site classification | F1: State | G1: Tower Type | H1: Height | I1: Year Built | J1: Anchor Tenant Name | K1: Capex
A2: 1 | B2: 405 | C2: High Lease Up Potential | D2: 100 | E2: Urban | F2: TX | G2: SST | H2: 225 | I2: 2022 | J2: Tenant B | K2: 129996.24
A3: 2 | B3: 233 | C3: High Lease Up Potential | D3: 97 | E3: Urban | F3: TX | G3: SST | H3: 210 | I3: 2019 | J3: Tenant B | K3: 101233.18
A4: 3 | B4: 403 | C4: High Lease Up Potential | D4: 97 | E4: Urban | F4: AZ | G4: SST | H4: 175 | I4: 2021 | J4: Tenant A | K4: 104416.8
A5: 4 | B5: 486 | C5: High Lease Up Potential | D5: 95 | E5: Urban | F5: TX | G5: Monopole | H5: 205 | I5: 2022 | J5: Tenant C | K5: 113963.75
A6: 5 | B6: 190 | C6: High Lease Up Potential | D6: 92 | E6: Urban | F6: TX | G6: Monopole | H6: 205 | I6: 2019 | J6: Tenant A | K6: 87276.16
A7: 6 | B7: 130 | C7: High Lease Up Potential | D7: 92 | E7: Urban | F7: OR | G7: SST | H7: 220 | I7: 2019 | J7: Tenant C | K7: 95341.7
A8: 7 | B8: 359 | C8: High Lease Up Potential | D8: 92 | E8: Urban | F8: PA | G8: SST | H8: 165 | I8: 2021 | J8: Tenant D | K8: 104685.6
A9: 8 | B9: 236 | C9: High Lease Up Potential | D9: 92 | E9: Urban | F9: OR | G9: SST | H9: 220 | I9: 2019 | J9: Tenant A | K9: 107577.8
A10: 9 | B10: 271 | C10: High Lease Up Potential | D10: 92 | E10: Urban | F10: FL | G10: SST | H10: 225 | I10: 2020 | J10: Tenant C | K10: 107876.25
A11: 10 | B11: 133 | C11: High Lease Up Potential | D11: 92 | E11: Urban | F11: OR | G11: SST | H11: 215 | I11: 2019 | J11: Tenant B | K11: 107933.44
A12: 11 | B12: 252 | C12: High Lease Up Potential | D12: 92 | E12: Urban | F12: FL | G12: SST | H12: 215 | I12: 2019 | J12: Tenant C | K12: 116251.26
A13: 12 | B13: 500 | C13: High Lease Up Potential | D13: 92 | E13: Urban | F13: FL | G13: SST | H13: 170 | I13: 2022 | J13: Tenant B | K13: 121382.5
... A425: 424 | B425: 484 | C425: Low Lease Up Potential | D425: 39 | E425: Rural | F425: OR | G425: Stealth - Monopine | H425: 100 | I425: 2022 | J425: Tenant A | K425: 112375

Sheet PayBack
A1: Site Number | B1: Site classification | C1: State | D1: Capex | E1: Anchor Tenant Starting Monthly Rent | F1: Ground Lease Rent OPEX | G1: Net_Annual_Income | H1: Payback_Years | I1: Payback_Category
A2: 5 | B2: Rural | C2: OR | D2: 20330 | E2: 950 | F2: 175 | G2: 9300 | H2: 2.1860215 | I2: 1-5 years Pay Back
A3: 153 | B3: Rural | C3: OR | D3: 21612.96 | E3: 975 | F3: 325 | G3: 7800 | H3: 2.7708923 | I3: 1-5 years Pay Back
A4: 94 | B4: Rural | C4: OR | D4: 21810.25 | E4: 875 | F4: 350 | G4: 6300 | H4: 3.4619444 | I4: 1-5 years Pay Back
A5: 61 | B5: Rural | C5: AZ | D5: 21848.4 | E5: 825 | F5: 375 | G5: 5400 | H5: 4.046 | I5: 1-5 years Pay Back
A6: 206 | B6: Rural | C6: PA | D6: 21913.38 | E6: 950 | F6: 350 | G6: 7200 | H6: 3.043525 | I6: 1-5 years Pay Back
A7: 223 | B7: Rural | C7: AZ | D7: 22600.6 | E7: 950 | F7: 225 | G7: 8700 | H7: 2.5977701 | I7: 1-5 years Pay Back
A8: 81 | B8: Rural | C8: PA | D8: 22632.19 | E8: 950 | F8: 300 | G8: 7800 | H8: 2.9015628 | I8: 1-5 years Pay Back
A9: 45 | B9: Rural | C9: OR | D9: 22866 | E9: 950 | F9: 275 | G9: 8100 | H9: 2.822963 | I9: 1-5 years Pay Back
A10: 42 | B10: Rural | C10: PA | D10: 23124.4 | E10: 950 | F10: 300 | G10: 7800 | H10: 2.9646667 | I10: 1-5 years Pay Back
A11: 46 | B11: Rural | C11: PA | D11: 23549.4 | E11: 950 | F11: 275 | G11: 8100 | H11: 2.9073333 | I11: 1-5 years Pay Back
A12: 234 | B12: Rural | C12: AZ | D12: 23569.7 | E12: 975 | F12: 225 | G12: 9000 | H12: 2.6188556 | I12: 1-5 years Pay Back
A13: 63 | B13: Rural | C13: PA | D13: 23647.52 | E13: 975 | F13: 350 | G13: 7500 | H13: 3.1530027 | I13: 1-5 years Pay Back
... A26: 399 | B26: Rural | C26: TX | D26: 25496.4 | E26: 950 | F26: 200 | G26: 9000 | H26: 2.8329333 | I26: 1-5 years Pay Back
A27: 6 | B27: Rural | C27: AZ | D27: 25682 | E27: 875 | G27: 10500 | H27: 2.4459048 | I27: 1-5 years Pay Back
A28: 357 | B28: Rural | C28: AZ | D28: 25762.8 | E28: 950 | F28: 250 | G28: 8400 | H28: 3.067 | I28: 1-5 years Pay Back
A29: 288 | B29: Rural | C29: PA | D29: 25816.8 | E29: 950 | F29: 325 | G29: 7500 | H29: 3.44224 | I29: 1-5 years Pay Back
A30: 60 | B30: Rural | C30: PA | D30: 26023.92 | E30: 975 | F30: 200 | G30: 9300 | H30: 2.798271 | I30: 1-5 years Pay Back
A31: 401 | B31: Rural | C31: OR | D31: 26030.4 | E31: 825 | F31: 350 | G31: 5700 | H31: 4.5667368 | I31: 1-5 years Pay Back
A32: 92 | B32: Rural | C32: AZ | D32: 26047.67 | E32: 975 | F32: 325 | G32: 7800 | H32: 3.3394449 | I32: 1-5 years Pay Back
A33: 465 | B33: Rural | C33: OR | D33: 26068.75 | E33: 950 | F33: 250 | G33: 8400 | H33: 3.1034226 | I33: 1-5 years Pay Back
A34: 150 | B34: Rural | C34: PA | D34: 26139.24 | E34: 950 | F34: 350 | G34: 7200 | H34: 3.63045 | I34: 1-5 years Pay Back
A35: 198 | B35: Rural | C35: PA | D35: 26142.48 | E35: 975 | F35: 175 | G35: 9600 | H35: 2.723175 | I35: 1-5 years Pay Back
A36: 208 | B36: Rural | C36: TX | D36: 26345.52 | E36: 825 | F36: 175 | G36: 7800 | H36: 3.3776308 | I36: 1-5 years Pay Back
A37: 87 | B37: Rural | C37: AZ | D37: 26408.17 | E37: 975 | F37: 350 | G37: 7500 | H37: 3.5210893 | I37: 1-5 years Pay Back
A38: 118 | B38: Rural | C38: PA | D38: 26424.3 | E38: 950 | F38: 325 | G38: 7500 | H38: 3.52324 | I38: 1-5 years Pay Back
A39: 311 | B39: Rural | C39: TX | D39: 26619.6 | E39: 875 | F39: 375 | G39: 6000 | H39: 4.4366 | I39: 1-5 years Pay Back
... A60: 88 | B60: Rural | C60: TX | D60: 28656.66 | E60: 950 | F60: 300 | G60: 7800 | H60: 3.6739308 | I60: 1-5 years Pay Back
A61: 413 | B61: Rural | C61: PA | D61: 28665.15 | E61: 825 | G61: 9900 | H61: 2.8954697 | I61: 1-5 years Pay Back
A62: 177 | B62: Rural | C62: OR | D62: 28757.8 | E62: 825 | F62: 325 | G62: 6000 | H62: 4.7929667 | I62: 1-5 years Pay Back
A63: 55 | B63: Rural | C63: TX | D63: 28861.63 | E63: 825 | F63: 325 | G63: 6000 | H63: 4.8102717 | I63: 1-5 years Pay Back
A64: 251 | B64: Rural | C64: FL | D64: 28901.96 | E64: 875 | F64: 150 | G64: 8700 | H64: 3.3220644 | I64: 1-5 years Pay Back
A65: 145 | B65: Rural | C65: FL | D65: 28924.22 | E65: 875 | F65: 325 | G65: 6600 | H65: 4.3824576 | I65: 1-5 years Pay Back
A66: 193 | B66: Rural | C66: PA | D66: 29115.02 | E66: 975 | F66: 325 | G66: 7800 | H66: 3.7326949 | I66: 1-5 years Pay Back
A67: 391 | B67: Rural | C67: OR | D67: 29400 | E67: 875 | F67: 325 | G67: 6600 | H67: 4.4545455 | I67: 1-5 years Pay Back
A68: 29 | B68: Rural | C68: PA | D68: 29622 | E68: 975 | F68: 350 | G68: 7500 | H68: 3.9496 | I68: 1-5 years Pay Back
A69: 323 | B69: Rural | C69: AZ | D69: 29636.4 | E69: 825 | F69: 200 | G69: 7500 | H69: 3.95152 | I69: 1-5 years Pay Back
A70: 254 | B70: Rural | C70: TX | D70: 29835.82 | E70: 950 | F70: 225 | G70: 8700 | H70: 3.4294046 | I70: 1-5 years Pay Back
A71: 427 | B71: Rural | C71: TX | D71: 29895.15 | E71: 950 | F71: 275 | G71: 8100 | H71: 3.6907593 | I71: 1-5 years Pay Back
A72: 491 | B72: Rural | C72: OR | D72: 29931.25 | E72: 875 | F72: 325 | G72: 6600 | H72: 4.5350379 | I72: 1-5 years Pay Back
...

Sheet OLDExecutive_Dashboard
D36: Pillar / Strategic Area | F36: Key Metric & Insight | I36: Risk / Opportunity | L36: Recommendation
D37: Pillar 1: Density & Growth | F37: 44.1% High Potential (187 sites) concentrated in Urban/Suburban hubs. | I37: Opportunity: High demand density and carrier network densification needs. | L37: Prioritize sales outreach & fast-track co-location leasing in Top Urban markets.
D38: Pillar 2: Structural Profile | F38: Monopole dominance (~60%) with structural capacity for 2–3 additional tenancy slots. | I38: Risk: Overloading existing structural limits without CapEx upgrades. | L38: Standardize structural modifications (RAD center extensions) for rapid carrier mounting.
D39: Pillar 3: Financial Profile | F39: Avg. CapEx per site: ~$308K; 68% of inventory falls in the 5–10 Year Payback tranche. | I39: Opportunity: High-potential sites yield accelerated ROI (12.6 yrs payback). | L39: Direct capital allocation toward sites with immediate multi-tenant leasing potential.
D40: Pillar 4: Age Profile | F40: Peak construction (2015–2019)accounts for the largest cohort of unleased assets. | I40: Risk: Aging structural assets may require deferred maintenance before tenancy. | L40: Audit 10+ year vintage sites for structural integrity during tenancy onboarding.
